2025-03-11T12:59:59,344 Using pip 24.0 from /home/kevin/Escritorio/universidad/universidad/lib/python3.12/site-packages/pip (python 3.12)
2025-03-11T12:59:59,344 Non-user install because user site-packages disabled
2025-03-11T12:59:59,374 Created temporary directory: /tmp/pip-build-tracker-zc6zq2af
2025-03-11T12:59:59,374 Initialized build tracking at /tmp/pip-build-tracker-zc6zq2af
2025-03-11T12:59:59,375 Created build tracker: /tmp/pip-build-tracker-zc6zq2af
2025-03-11T12:59:59,375 Entered build tracker: /tmp/pip-build-tracker-zc6zq2af
2025-03-11T12:59:59,375 Created temporary directory: /tmp/pip-install-c9ack598
2025-03-11T12:59:59,375 Created temporary directory: /tmp/pip-ephem-wheel-cache-jwyemwox
2025-03-11T12:59:59,382 1 location(s) to search for versions of install:
2025-03-11T12:59:59,382 * https://pypi.org/simple/install/
2025-03-11T12:59:59,382 Fetching project page and analyzing links: https://pypi.org/simple/install/
2025-03-11T12:59:59,382 Getting page https://pypi.org/simple/install/
2025-03-11T12:59:59,382 Found index url https://pypi.org/simple/
2025-03-11T12:59:59,592 Could not fetch URL https://pypi.org/simple/install/: 404 Client Error: Not Found for url: https://pypi.org/simple/install/ - skipping
2025-03-11T12:59:59,592 Skipping link: not a file: https://pypi.org/simple/install/
2025-03-11T12:59:59,599 Given no hashes to check 0 links for project 'install': discarding no candidates
2025-03-11T12:59:59,599 ERROR: Could not find a version that satisfies the requirement install (from versions: none)
2025-03-11T12:59:59,600 ERROR: No matching distribution found for install
2025-03-11T12:59:59,601 Exception information:
2025-03-11T12:59:59,601 Traceback (most recent call last):
2025-03-11T12:59:59,601   File "/home/kevin/Escritorio/universidad/universidad/lib/python3.12/site-packages/pip/_vendor/resolvelib/resolvers.py", line 397, in resolve
2025-03-11T12:59:59,601     self._add_to_criteria(self.state.criteria, r, parent=None)
2025-03-11T12:59:59,601   File "/home/kevin/Escritorio/universidad/universidad/lib/python3.12/site-packages/pip/_vendor/resolvelib/resolvers.py", line 174, in _add_to_criteria
2025-03-11T12:59:59,601     raise RequirementsConflicted(criterion)
2025-03-11T12:59:59,601 pip._vendor.resolvelib.resolvers.RequirementsConflicted: Requirements conflict: SpecifierRequirement('install')
2025-03-11T12:59:59,601 
2025-03-11T12:59:59,601 During handling of the above exception, another exception occurred:
2025-03-11T12:59:59,601 
2025-03-11T12:59:59,601 Traceback (most recent call last):
2025-03-11T12:59:59,601   File "/home/kevin/Escritorio/universidad/universidad/lib/python3.12/site-packages/pip/_internal/resolution/resolvelib/resolver.py", line 95, in resolve
2025-03-11T12:59:59,601     result = self._result = resolver.resolve(
2025-03-11T12:59:59,601                             ^^^^^^^^^^^^^^^^^
2025-03-11T12:59:59,601   File "/home/kevin/Escritorio/universidad/universidad/lib/python3.12/site-packages/pip/_vendor/resolvelib/resolvers.py", line 546, in resolve
2025-03-11T12:59:59,601     state = resolution.resolve(requirements, max_rounds=max_rounds)
2025-03-11T12:59:59,601             ^^^^^^^^^^^^^^^^^^^^^^^^^^^^^^^^^^^^^^^^^^^^^^^^^^^^^^^
2025-03-11T12:59:59,601   File "/home/kevin/Escritorio/universidad/universidad/lib/python3.12/site-packages/pip/_vendor/resolvelib/resolvers.py", line 399, in resolve
2025-03-11T12:59:59,601     raise ResolutionImpossible(e.criterion.information)
2025-03-11T12:59:59,601 pip._vendor.resolvelib.resolvers.ResolutionImpossible: [RequirementInformation(requirement=SpecifierRequirement('install'), parent=None)]
2025-03-11T12:59:59,601 
2025-03-11T12:59:59,601 The above exception was the direct cause of the following exception:
2025-03-11T12:59:59,601 
2025-03-11T12:59:59,601 Traceback (most recent call last):
2025-03-11T12:59:59,601   File "/home/kevin/Escritorio/universidad/universidad/lib/python3.12/site-packages/pip/_internal/cli/base_command.py", line 180, in exc_logging_wrapper
2025-03-11T12:59:59,601     status = run_func(*args)
2025-03-11T12:59:59,601              ^^^^^^^^^^^^^^^
2025-03-11T12:59:59,601   File "/home/kevin/Escritorio/universidad/universidad/lib/python3.12/site-packages/pip/_internal/cli/req_command.py", line 245, in wrapper
2025-03-11T12:59:59,601     return func(self, options, args)
2025-03-11T12:59:59,601            ^^^^^^^^^^^^^^^^^^^^^^^^^
2025-03-11T12:59:59,601   File "/home/kevin/Escritorio/universidad/universidad/lib/python3.12/site-packages/pip/_internal/commands/install.py", line 377, in run
2025-03-11T12:59:59,601     requirement_set = resolver.resolve(
2025-03-11T12:59:59,601                       ^^^^^^^^^^^^^^^^^
2025-03-11T12:59:59,601   File "/home/kevin/Escritorio/universidad/universidad/lib/python3.12/site-packages/pip/_internal/resolution/resolvelib/resolver.py", line 104, in resolve
2025-03-11T12:59:59,601     raise error from e
2025-03-11T12:59:59,601 pip._internal.exceptions.DistributionNotFound: No matching distribution found for install
2025-03-11T12:59:59,612 Removed build tracker: '/tmp/pip-build-tracker-zc6zq2af'
2025-03-11T13:08:53,816 Using pip 24.0 from /home/kevin/Escritorio/universidad/universidad/lib/python3.12/site-packages/pip (python 3.12)
2025-03-11T13:08:53,816 Non-user install because user site-packages disabled
2025-03-11T13:08:53,847 Created temporary directory: /tmp/pip-build-tracker-lljvib_5
2025-03-11T13:08:53,847 Initialized build tracking at /tmp/pip-build-tracker-lljvib_5
2025-03-11T13:08:53,847 Created build tracker: /tmp/pip-build-tracker-lljvib_5
2025-03-11T13:08:53,847 Entered build tracker: /tmp/pip-build-tracker-lljvib_5
2025-03-11T13:08:53,847 Created temporary directory: /tmp/pip-install-grd8w9eo
2025-03-11T13:08:53,847 Created temporary directory: /tmp/pip-ephem-wheel-cache-0o74155e
2025-03-11T13:08:53,852 1 location(s) to search for versions of list:
2025-03-11T13:08:53,852 * https://pypi.org/simple/list/
2025-03-11T13:08:53,853 Fetching project page and analyzing links: https://pypi.org/simple/list/
2025-03-11T13:08:53,853 Getting page https://pypi.org/simple/list/
2025-03-11T13:08:53,853 Found index url https://pypi.org/simple/
2025-03-11T13:08:54,061 Could not fetch URL https://pypi.org/simple/list/: 404 Client Error: Not Found for url: https://pypi.org/simple/list/ - skipping
2025-03-11T13:08:54,062 Skipping link: not a file: https://pypi.org/simple/list/
2025-03-11T13:08:54,070 Given no hashes to check 0 links for project 'list': discarding no candidates
2025-03-11T13:08:54,070 ERROR: Could not find a version that satisfies the requirement list (from versions: none)
2025-03-11T13:08:54,071 ERROR: No matching distribution found for list
2025-03-11T13:08:54,072 Exception information:
2025-03-11T13:08:54,072 Traceback (most recent call last):
2025-03-11T13:08:54,072   File "/home/kevin/Escritorio/universidad/universidad/lib/python3.12/site-packages/pip/_vendor/resolvelib/resolvers.py", line 397, in resolve
2025-03-11T13:08:54,072     self._add_to_criteria(self.state.criteria, r, parent=None)
2025-03-11T13:08:54,072   File "/home/kevin/Escritorio/universidad/universidad/lib/python3.12/site-packages/pip/_vendor/resolvelib/resolvers.py", line 174, in _add_to_criteria
2025-03-11T13:08:54,072     raise RequirementsConflicted(criterion)
2025-03-11T13:08:54,072 pip._vendor.resolvelib.resolvers.RequirementsConflicted: Requirements conflict: SpecifierRequirement('list')
2025-03-11T13:08:54,072 
2025-03-11T13:08:54,072 During handling of the above exception, another exception occurred:
2025-03-11T13:08:54,072 
2025-03-11T13:08:54,072 Traceback (most recent call last):
2025-03-11T13:08:54,072   File "/home/kevin/Escritorio/universidad/universidad/lib/python3.12/site-packages/pip/_internal/resolution/resolvelib/resolver.py", line 95, in resolve
2025-03-11T13:08:54,072     result = self._result = resolver.resolve(
2025-03-11T13:08:54,072                             ^^^^^^^^^^^^^^^^^
2025-03-11T13:08:54,072   File "/home/kevin/Escritorio/universidad/universidad/lib/python3.12/site-packages/pip/_vendor/resolvelib/resolvers.py", line 546, in resolve
2025-03-11T13:08:54,072     state = resolution.resolve(requirements, max_rounds=max_rounds)
2025-03-11T13:08:54,072             ^^^^^^^^^^^^^^^^^^^^^^^^^^^^^^^^^^^^^^^^^^^^^^^^^^^^^^^
2025-03-11T13:08:54,072   File "/home/kevin/Escritorio/universidad/universidad/lib/python3.12/site-packages/pip/_vendor/resolvelib/resolvers.py", line 399, in resolve
2025-03-11T13:08:54,072     raise ResolutionImpossible(e.criterion.information)
2025-03-11T13:08:54,072 pip._vendor.resolvelib.resolvers.ResolutionImpossible: [RequirementInformation(requirement=SpecifierRequirement('list'), parent=None)]
2025-03-11T13:08:54,072 
2025-03-11T13:08:54,072 The above exception was the direct cause of the following exception:
2025-03-11T13:08:54,072 
2025-03-11T13:08:54,072 Traceback (most recent call last):
2025-03-11T13:08:54,072   File "/home/kevin/Escritorio/universidad/universidad/lib/python3.12/site-packages/pip/_internal/cli/base_command.py", line 180, in exc_logging_wrapper
2025-03-11T13:08:54,072     status = run_func(*args)
2025-03-11T13:08:54,072              ^^^^^^^^^^^^^^^
2025-03-11T13:08:54,072   File "/home/kevin/Escritorio/universidad/universidad/lib/python3.12/site-packages/pip/_internal/cli/req_command.py", line 245, in wrapper
2025-03-11T13:08:54,072     return func(self, options, args)
2025-03-11T13:08:54,072            ^^^^^^^^^^^^^^^^^^^^^^^^^
2025-03-11T13:08:54,072   File "/home/kevin/Escritorio/universidad/universidad/lib/python3.12/site-packages/pip/_internal/commands/install.py", line 377, in run
2025-03-11T13:08:54,072     requirement_set = resolver.resolve(
2025-03-11T13:08:54,072                       ^^^^^^^^^^^^^^^^^
2025-03-11T13:08:54,072   File "/home/kevin/Escritorio/universidad/universidad/lib/python3.12/site-packages/pip/_internal/resolution/resolvelib/resolver.py", line 104, in resolve
2025-03-11T13:08:54,072     raise error from e
2025-03-11T13:08:54,072 pip._internal.exceptions.DistributionNotFound: No matching distribution found for list
2025-03-11T13:08:54,074 Removed build tracker: '/tmp/pip-build-tracker-lljvib_5'
2025-03-11T13:09:04,300 Using pip 24.0 from /home/kevin/Escritorio/universidad/universidad/lib/python3.12/site-packages/pip (python 3.12)
2025-03-11T13:09:04,300 Non-user install because user site-packages disabled
2025-03-11T13:09:04,327 Created temporary directory: /tmp/pip-build-tracker-j99l1atz
2025-03-11T13:09:04,328 Initialized build tracking at /tmp/pip-build-tracker-j99l1atz
2025-03-11T13:09:04,328 Created build tracker: /tmp/pip-build-tracker-j99l1atz
2025-03-11T13:09:04,328 Entered build tracker: /tmp/pip-build-tracker-j99l1atz
2025-03-11T13:09:04,328 Created temporary directory: /tmp/pip-install-9n4y4p8m
2025-03-11T13:09:04,328 Created temporary directory: /tmp/pip-ephem-wheel-cache-94rguuiq
2025-03-11T13:09:04,334 1 location(s) to search for versions of freeze:
2025-03-11T13:09:04,334 * https://pypi.org/simple/freeze/
2025-03-11T13:09:04,334 Fetching project page and analyzing links: https://pypi.org/simple/freeze/
2025-03-11T13:09:04,334 Getting page https://pypi.org/simple/freeze/
2025-03-11T13:09:04,335 Found index url https://pypi.org/simple/
2025-03-11T13:09:04,550 Could not fetch URL https://pypi.org/simple/freeze/: 404 Client Error: Not Found for url: https://pypi.org/simple/freeze/ - skipping
2025-03-11T13:09:04,550 Skipping link: not a file: https://pypi.org/simple/freeze/
2025-03-11T13:09:04,557 Given no hashes to check 0 links for project 'freeze': discarding no candidates
2025-03-11T13:09:04,557 ERROR: Could not find a version that satisfies the requirement freeze (from versions: none)
2025-03-11T13:09:04,557 ERROR: No matching distribution found for freeze
2025-03-11T13:09:04,557 Exception information:
2025-03-11T13:09:04,557 Traceback (most recent call last):
2025-03-11T13:09:04,557   File "/home/kevin/Escritorio/universidad/universidad/lib/python3.12/site-packages/pip/_vendor/resolvelib/resolvers.py", line 397, in resolve
2025-03-11T13:09:04,557     self._add_to_criteria(self.state.criteria, r, parent=None)
2025-03-11T13:09:04,557   File "/home/kevin/Escritorio/universidad/universidad/lib/python3.12/site-packages/pip/_vendor/resolvelib/resolvers.py", line 174, in _add_to_criteria
2025-03-11T13:09:04,557     raise RequirementsConflicted(criterion)
2025-03-11T13:09:04,557 pip._vendor.resolvelib.resolvers.RequirementsConflicted: Requirements conflict: SpecifierRequirement('freeze')
2025-03-11T13:09:04,557 
2025-03-11T13:09:04,557 During handling of the above exception, another exception occurred:
2025-03-11T13:09:04,557 
2025-03-11T13:09:04,557 Traceback (most recent call last):
2025-03-11T13:09:04,557   File "/home/kevin/Escritorio/universidad/universidad/lib/python3.12/site-packages/pip/_internal/resolution/resolvelib/resolver.py", line 95, in resolve
2025-03-11T13:09:04,557     result = self._result = resolver.resolve(
2025-03-11T13:09:04,557                             ^^^^^^^^^^^^^^^^^
2025-03-11T13:09:04,557   File "/home/kevin/Escritorio/universidad/universidad/lib/python3.12/site-packages/pip/_vendor/resolvelib/resolvers.py", line 546, in resolve
2025-03-11T13:09:04,557     state = resolution.resolve(requirements, max_rounds=max_rounds)
2025-03-11T13:09:04,557             ^^^^^^^^^^^^^^^^^^^^^^^^^^^^^^^^^^^^^^^^^^^^^^^^^^^^^^^
2025-03-11T13:09:04,557   File "/home/kevin/Escritorio/universidad/universidad/lib/python3.12/site-packages/pip/_vendor/resolvelib/resolvers.py", line 399, in resolve
2025-03-11T13:09:04,557     raise ResolutionImpossible(e.criterion.information)
2025-03-11T13:09:04,557 pip._vendor.resolvelib.resolvers.ResolutionImpossible: [RequirementInformation(requirement=SpecifierRequirement('freeze'), parent=None)]
2025-03-11T13:09:04,557 
2025-03-11T13:09:04,557 The above exception was the direct cause of the following exception:
2025-03-11T13:09:04,557 
2025-03-11T13:09:04,557 Traceback (most recent call last):
2025-03-11T13:09:04,557   File "/home/kevin/Escritorio/universidad/universidad/lib/python3.12/site-packages/pip/_internal/cli/base_command.py", line 180, in exc_logging_wrapper
2025-03-11T13:09:04,557     status = run_func(*args)
2025-03-11T13:09:04,557              ^^^^^^^^^^^^^^^
2025-03-11T13:09:04,557   File "/home/kevin/Escritorio/universidad/universidad/lib/python3.12/site-packages/pip/_internal/cli/req_command.py", line 245, in wrapper
2025-03-11T13:09:04,557     return func(self, options, args)
2025-03-11T13:09:04,557            ^^^^^^^^^^^^^^^^^^^^^^^^^
2025-03-11T13:09:04,557   File "/home/kevin/Escritorio/universidad/universidad/lib/python3.12/site-packages/pip/_internal/commands/install.py", line 377, in run
2025-03-11T13:09:04,557     requirement_set = resolver.resolve(
2025-03-11T13:09:04,557                       ^^^^^^^^^^^^^^^^^
2025-03-11T13:09:04,557   File "/home/kevin/Escritorio/universidad/universidad/lib/python3.12/site-packages/pip/_internal/resolution/resolvelib/resolver.py", line 104, in resolve
2025-03-11T13:09:04,557     raise error from e
2025-03-11T13:09:04,557 pip._internal.exceptions.DistributionNotFound: No matching distribution found for freeze
2025-03-11T13:09:04,558 Removed build tracker: '/tmp/pip-build-tracker-j99l1atz'
2025-03-11T13:12:26,270 Using pip 24.0 from /home/kevin/Escritorio/universidad/universidad/lib/python3.12/site-packages/pip (python 3.12)
2025-03-11T13:12:26,270 Non-user install because user site-packages disabled
2025-03-11T13:12:26,300 Created temporary directory: /tmp/pip-build-tracker-rfyg26lu
2025-03-11T13:12:26,300 Initialized build tracking at /tmp/pip-build-tracker-rfyg26lu
2025-03-11T13:12:26,300 Created build tracker: /tmp/pip-build-tracker-rfyg26lu
2025-03-11T13:12:26,300 Entered build tracker: /tmp/pip-build-tracker-rfyg26lu
2025-03-11T13:12:26,300 Created temporary directory: /tmp/pip-install-6o8k_uvi
2025-03-11T13:12:26,301 Created temporary directory: /tmp/pip-ephem-wheel-cache-1fks44r1
2025-03-11T13:12:26,309 1 location(s) to search for versions of list:
2025-03-11T13:12:26,309 * https://pypi.org/simple/list/
2025-03-11T13:12:26,309 Fetching project page and analyzing links: https://pypi.org/simple/list/
2025-03-11T13:12:26,309 Getting page https://pypi.org/simple/list/
2025-03-11T13:12:26,309 Found index url https://pypi.org/simple/
2025-03-11T13:12:26,687 Could not fetch URL https://pypi.org/simple/list/: 404 Client Error: Not Found for url: https://pypi.org/simple/list/ - skipping
2025-03-11T13:12:26,687 Skipping link: not a file: https://pypi.org/simple/list/
2025-03-11T13:12:26,696 Given no hashes to check 0 links for project 'list': discarding no candidates
2025-03-11T13:12:26,696 ERROR: Could not find a version that satisfies the requirement list (from versions: none)
2025-03-11T13:12:26,697 ERROR: No matching distribution found for list
2025-03-11T13:12:26,697 Exception information:
2025-03-11T13:12:26,697 Traceback (most recent call last):
2025-03-11T13:12:26,697   File "/home/kevin/Escritorio/universidad/universidad/lib/python3.12/site-packages/pip/_vendor/resolvelib/resolvers.py", line 397, in resolve
2025-03-11T13:12:26,697     self._add_to_criteria(self.state.criteria, r, parent=None)
2025-03-11T13:12:26,697   File "/home/kevin/Escritorio/universidad/universidad/lib/python3.12/site-packages/pip/_vendor/resolvelib/resolvers.py", line 174, in _add_to_criteria
2025-03-11T13:12:26,697     raise RequirementsConflicted(criterion)
2025-03-11T13:12:26,697 pip._vendor.resolvelib.resolvers.RequirementsConflicted: Requirements conflict: SpecifierRequirement('list')
2025-03-11T13:12:26,697 
2025-03-11T13:12:26,697 During handling of the above exception, another exception occurred:
2025-03-11T13:12:26,697 
2025-03-11T13:12:26,697 Traceback (most recent call last):
2025-03-11T13:12:26,697   File "/home/kevin/Escritorio/universidad/universidad/lib/python3.12/site-packages/pip/_internal/resolution/resolvelib/resolver.py", line 95, in resolve
2025-03-11T13:12:26,697     result = self._result = resolver.resolve(
2025-03-11T13:12:26,697                             ^^^^^^^^^^^^^^^^^
2025-03-11T13:12:26,697   File "/home/kevin/Escritorio/universidad/universidad/lib/python3.12/site-packages/pip/_vendor/resolvelib/resolvers.py", line 546, in resolve
2025-03-11T13:12:26,697     state = resolution.resolve(requirements, max_rounds=max_rounds)
2025-03-11T13:12:26,697             ^^^^^^^^^^^^^^^^^^^^^^^^^^^^^^^^^^^^^^^^^^^^^^^^^^^^^^^
2025-03-11T13:12:26,697   File "/home/kevin/Escritorio/universidad/universidad/lib/python3.12/site-packages/pip/_vendor/resolvelib/resolvers.py", line 399, in resolve
2025-03-11T13:12:26,697     raise ResolutionImpossible(e.criterion.information)
2025-03-11T13:12:26,697 pip._vendor.resolvelib.resolvers.ResolutionImpossible: [RequirementInformation(requirement=SpecifierRequirement('list'), parent=None)]
2025-03-11T13:12:26,697 
2025-03-11T13:12:26,697 The above exception was the direct cause of the following exception:
2025-03-11T13:12:26,697 
2025-03-11T13:12:26,697 Traceback (most recent call last):
2025-03-11T13:12:26,697   File "/home/kevin/Escritorio/universidad/universidad/lib/python3.12/site-packages/pip/_internal/cli/base_command.py", line 180, in exc_logging_wrapper
2025-03-11T13:12:26,697     status = run_func(*args)
2025-03-11T13:12:26,697              ^^^^^^^^^^^^^^^
2025-03-11T13:12:26,697   File "/home/kevin/Escritorio/universidad/universidad/lib/python3.12/site-packages/pip/_internal/cli/req_command.py", line 245, in wrapper
2025-03-11T13:12:26,697     return func(self, options, args)
2025-03-11T13:12:26,697            ^^^^^^^^^^^^^^^^^^^^^^^^^
2025-03-11T13:12:26,697   File "/home/kevin/Escritorio/universidad/universidad/lib/python3.12/site-packages/pip/_internal/commands/install.py", line 377, in run
2025-03-11T13:12:26,697     requirement_set = resolver.resolve(
2025-03-11T13:12:26,697                       ^^^^^^^^^^^^^^^^^
2025-03-11T13:12:26,697   File "/home/kevin/Escritorio/universidad/universidad/lib/python3.12/site-packages/pip/_internal/resolution/resolvelib/resolver.py", line 104, in resolve
2025-03-11T13:12:26,697     raise error from e
2025-03-11T13:12:26,697 pip._internal.exceptions.DistributionNotFound: No matching distribution found for list
2025-03-11T13:12:26,699 Removed build tracker: '/tmp/pip-build-tracker-rfyg26lu'
2025-03-11T13:15:38,305 Using pip 24.0 from /home/kevin/Escritorio/universidad/universidad/lib/python3.12/site-packages/pip (python 3.12)
2025-03-11T13:15:38,305 Non-user install because user site-packages disabled
2025-03-11T13:15:38,338 Created temporary directory: /tmp/pip-build-tracker-2lc_kltq
2025-03-11T13:15:38,338 Initialized build tracking at /tmp/pip-build-tracker-2lc_kltq
2025-03-11T13:15:38,338 Created build tracker: /tmp/pip-build-tracker-2lc_kltq
2025-03-11T13:15:38,338 Entered build tracker: /tmp/pip-build-tracker-2lc_kltq
2025-03-11T13:15:38,338 Created temporary directory: /tmp/pip-install-o4wjwz3z
2025-03-11T13:15:38,339 Created temporary directory: /tmp/pip-ephem-wheel-cache-teqgigc9
2025-03-11T13:15:38,345 1 location(s) to search for versions of freeze:
2025-03-11T13:15:38,345 * https://pypi.org/simple/freeze/
2025-03-11T13:15:38,345 Fetching project page and analyzing links: https://pypi.org/simple/freeze/
2025-03-11T13:15:38,346 Getting page https://pypi.org/simple/freeze/
2025-03-11T13:15:38,346 Found index url https://pypi.org/simple/
2025-03-11T13:15:38,666 Could not fetch URL https://pypi.org/simple/freeze/: 404 Client Error: Not Found for url: https://pypi.org/simple/freeze/ - skipping
2025-03-11T13:15:38,667 Skipping link: not a file: https://pypi.org/simple/freeze/
2025-03-11T13:15:38,674 Given no hashes to check 0 links for project 'freeze': discarding no candidates
2025-03-11T13:15:38,674 ERROR: Could not find a version that satisfies the requirement freeze (from versions: none)
2025-03-11T13:15:38,675 ERROR: No matching distribution found for freeze
2025-03-11T13:15:38,676 Exception information:
2025-03-11T13:15:38,676 Traceback (most recent call last):
2025-03-11T13:15:38,676   File "/home/kevin/Escritorio/universidad/universidad/lib/python3.12/site-packages/pip/_vendor/resolvelib/resolvers.py", line 397, in resolve
2025-03-11T13:15:38,676     self._add_to_criteria(self.state.criteria, r, parent=None)
2025-03-11T13:15:38,676   File "/home/kevin/Escritorio/universidad/universidad/lib/python3.12/site-packages/pip/_vendor/resolvelib/resolvers.py", line 174, in _add_to_criteria
2025-03-11T13:15:38,676     raise RequirementsConflicted(criterion)
2025-03-11T13:15:38,676 pip._vendor.resolvelib.resolvers.RequirementsConflicted: Requirements conflict: SpecifierRequirement('freeze')
2025-03-11T13:15:38,676 
2025-03-11T13:15:38,676 During handling of the above exception, another exception occurred:
2025-03-11T13:15:38,676 
2025-03-11T13:15:38,676 Traceback (most recent call last):
2025-03-11T13:15:38,676   File "/home/kevin/Escritorio/universidad/universidad/lib/python3.12/site-packages/pip/_internal/resolution/resolvelib/resolver.py", line 95, in resolve
2025-03-11T13:15:38,676     result = self._result = resolver.resolve(
2025-03-11T13:15:38,676                             ^^^^^^^^^^^^^^^^^
2025-03-11T13:15:38,676   File "/home/kevin/Escritorio/universidad/universidad/lib/python3.12/site-packages/pip/_vendor/resolvelib/resolvers.py", line 546, in resolve
2025-03-11T13:15:38,676     state = resolution.resolve(requirements, max_rounds=max_rounds)
2025-03-11T13:15:38,676             ^^^^^^^^^^^^^^^^^^^^^^^^^^^^^^^^^^^^^^^^^^^^^^^^^^^^^^^
2025-03-11T13:15:38,676   File "/home/kevin/Escritorio/universidad/universidad/lib/python3.12/site-packages/pip/_vendor/resolvelib/resolvers.py", line 399, in resolve
2025-03-11T13:15:38,676     raise ResolutionImpossible(e.criterion.information)
2025-03-11T13:15:38,676 pip._vendor.resolvelib.resolvers.ResolutionImpossible: [RequirementInformation(requirement=SpecifierRequirement('freeze'), parent=None)]
2025-03-11T13:15:38,676 
2025-03-11T13:15:38,676 The above exception was the direct cause of the following exception:
2025-03-11T13:15:38,676 
2025-03-11T13:15:38,676 Traceback (most recent call last):
2025-03-11T13:15:38,676   File "/home/kevin/Escritorio/universidad/universidad/lib/python3.12/site-packages/pip/_internal/cli/base_command.py", line 180, in exc_logging_wrapper
2025-03-11T13:15:38,676     status = run_func(*args)
2025-03-11T13:15:38,676              ^^^^^^^^^^^^^^^
2025-03-11T13:15:38,676   File "/home/kevin/Escritorio/universidad/universidad/lib/python3.12/site-packages/pip/_internal/cli/req_command.py", line 245, in wrapper
2025-03-11T13:15:38,676     return func(self, options, args)
2025-03-11T13:15:38,676            ^^^^^^^^^^^^^^^^^^^^^^^^^
2025-03-11T13:15:38,676   File "/home/kevin/Escritorio/universidad/universidad/lib/python3.12/site-packages/pip/_internal/commands/install.py", line 377, in run
2025-03-11T13:15:38,676     requirement_set = resolver.resolve(
2025-03-11T13:15:38,676                       ^^^^^^^^^^^^^^^^^
2025-03-11T13:15:38,676   File "/home/kevin/Escritorio/universidad/universidad/lib/python3.12/site-packages/pip/_internal/resolution/resolvelib/resolver.py", line 104, in resolve
2025-03-11T13:15:38,676     raise error from e
2025-03-11T13:15:38,676 pip._internal.exceptions.DistributionNotFound: No matching distribution found for freeze
2025-03-11T13:15:38,678 Removed build tracker: '/tmp/pip-build-tracker-2lc_kltq'
2025-03-11T13:18:14,351 Using pip 24.0 from /home/kevin/Escritorio/universidad/universidad/lib/python3.12/site-packages/pip (python 3.12)
2025-03-11T13:18:14,351 Non-user install because user site-packages disabled
2025-03-11T13:18:14,377 Created temporary directory: /tmp/pip-build-tracker-e9zyvtnh
2025-03-11T13:18:14,378 Initialized build tracking at /tmp/pip-build-tracker-e9zyvtnh
2025-03-11T13:18:14,378 Created build tracker: /tmp/pip-build-tracker-e9zyvtnh
2025-03-11T13:18:14,378 Entered build tracker: /tmp/pip-build-tracker-e9zyvtnh
2025-03-11T13:18:14,378 Created temporary directory: /tmp/pip-install-wx1di65m
2025-03-11T13:18:14,378 Created temporary directory: /tmp/pip-ephem-wheel-cache-8w133acp
2025-03-11T13:18:14,385 1 location(s) to search for versions of 24-0:
2025-03-11T13:18:14,385 * https://pypi.org/simple/24-0/
2025-03-11T13:18:14,385 Fetching project page and analyzing links: https://pypi.org/simple/24-0/
2025-03-11T13:18:14,385 Getting page https://pypi.org/simple/24-0/
2025-03-11T13:18:14,385 Found index url https://pypi.org/simple/
2025-03-11T13:18:14,717 Could not fetch URL https://pypi.org/simple/24-0/: 404 Client Error: Not Found for url: https://pypi.org/simple/24-0/ - skipping
2025-03-11T13:18:14,717 Skipping link: not a file: https://pypi.org/simple/24-0/
2025-03-11T13:18:14,724 Given no hashes to check 0 links for project '24-0': discarding no candidates
2025-03-11T13:18:14,724 ERROR: Could not find a version that satisfies the requirement 24.0 (from versions: none)
2025-03-11T13:18:14,725 ERROR: No matching distribution found for 24.0
2025-03-11T13:18:14,725 Exception information:
2025-03-11T13:18:14,725 Traceback (most recent call last):
2025-03-11T13:18:14,725   File "/home/kevin/Escritorio/universidad/universidad/lib/python3.12/site-packages/pip/_vendor/resolvelib/resolvers.py", line 397, in resolve
2025-03-11T13:18:14,725     self._add_to_criteria(self.state.criteria, r, parent=None)
2025-03-11T13:18:14,725   File "/home/kevin/Escritorio/universidad/universidad/lib/python3.12/site-packages/pip/_vendor/resolvelib/resolvers.py", line 174, in _add_to_criteria
2025-03-11T13:18:14,725     raise RequirementsConflicted(criterion)
2025-03-11T13:18:14,725 pip._vendor.resolvelib.resolvers.RequirementsConflicted: Requirements conflict: SpecifierRequirement('24.0')
2025-03-11T13:18:14,725 
2025-03-11T13:18:14,725 During handling of the above exception, another exception occurred:
2025-03-11T13:18:14,725 
2025-03-11T13:18:14,725 Traceback (most recent call last):
2025-03-11T13:18:14,725   File "/home/kevin/Escritorio/universidad/universidad/lib/python3.12/site-packages/pip/_internal/resolution/resolvelib/resolver.py", line 95, in resolve
2025-03-11T13:18:14,725     result = self._result = resolver.resolve(
2025-03-11T13:18:14,725                             ^^^^^^^^^^^^^^^^^
2025-03-11T13:18:14,725   File "/home/kevin/Escritorio/universidad/universidad/lib/python3.12/site-packages/pip/_vendor/resolvelib/resolvers.py", line 546, in resolve
2025-03-11T13:18:14,725     state = resolution.resolve(requirements, max_rounds=max_rounds)
2025-03-11T13:18:14,725             ^^^^^^^^^^^^^^^^^^^^^^^^^^^^^^^^^^^^^^^^^^^^^^^^^^^^^^^
2025-03-11T13:18:14,725   File "/home/kevin/Escritorio/universidad/universidad/lib/python3.12/site-packages/pip/_vendor/resolvelib/resolvers.py", line 399, in resolve
2025-03-11T13:18:14,725     raise ResolutionImpossible(e.criterion.information)
2025-03-11T13:18:14,725 pip._vendor.resolvelib.resolvers.ResolutionImpossible: [RequirementInformation(requirement=SpecifierRequirement('24.0'), parent=None)]
2025-03-11T13:18:14,725 
2025-03-11T13:18:14,725 The above exception was the direct cause of the following exception:
2025-03-11T13:18:14,725 
2025-03-11T13:18:14,725 Traceback (most recent call last):
2025-03-11T13:18:14,725   File "/home/kevin/Escritorio/universidad/universidad/lib/python3.12/site-packages/pip/_internal/cli/base_command.py", line 180, in exc_logging_wrapper
2025-03-11T13:18:14,725     status = run_func(*args)
2025-03-11T13:18:14,725              ^^^^^^^^^^^^^^^
2025-03-11T13:18:14,725   File "/home/kevin/Escritorio/universidad/universidad/lib/python3.12/site-packages/pip/_internal/cli/req_command.py", line 245, in wrapper
2025-03-11T13:18:14,725     return func(self, options, args)
2025-03-11T13:18:14,725            ^^^^^^^^^^^^^^^^^^^^^^^^^
2025-03-11T13:18:14,725   File "/home/kevin/Escritorio/universidad/universidad/lib/python3.12/site-packages/pip/_internal/commands/install.py", line 377, in run
2025-03-11T13:18:14,725     requirement_set = resolver.resolve(
2025-03-11T13:18:14,725                       ^^^^^^^^^^^^^^^^^
2025-03-11T13:18:14,725   File "/home/kevin/Escritorio/universidad/universidad/lib/python3.12/site-packages/pip/_internal/resolution/resolvelib/resolver.py", line 104, in resolve
2025-03-11T13:18:14,725     raise error from e
2025-03-11T13:18:14,725 pip._internal.exceptions.DistributionNotFound: No matching distribution found for 24.0
2025-03-11T13:18:14,726 Removed build tracker: '/tmp/pip-build-tracker-e9zyvtnh'
2025-03-11T13:18:30,754 Using pip 24.0 from /home/kevin/Escritorio/universidad/universidad/lib/python3.12/site-packages/pip (python 3.12)
2025-03-11T13:18:30,754 Non-user install because user site-packages disabled
2025-03-11T13:18:30,780 Created temporary directory: /tmp/pip-build-tracker-0mmx0nce
2025-03-11T13:18:30,780 Initialized build tracking at /tmp/pip-build-tracker-0mmx0nce
2025-03-11T13:18:30,780 Created build tracker: /tmp/pip-build-tracker-0mmx0nce
2025-03-11T13:18:30,780 Entered build tracker: /tmp/pip-build-tracker-0mmx0nce
2025-03-11T13:18:30,780 Created temporary directory: /tmp/pip-install-6qhudmii
2025-03-11T13:18:30,781 Created temporary directory: /tmp/pip-ephem-wheel-cache-bdfe4l7x
2025-03-11T13:18:30,786 1 location(s) to search for versions of freeze:
2025-03-11T13:18:30,786 * https://pypi.org/simple/freeze/
2025-03-11T13:18:30,787 Fetching project page and analyzing links: https://pypi.org/simple/freeze/
2025-03-11T13:18:30,787 Getting page https://pypi.org/simple/freeze/
2025-03-11T13:18:30,787 Found index url https://pypi.org/simple/
2025-03-11T13:18:31,076 Could not fetch URL https://pypi.org/simple/freeze/: 404 Client Error: Not Found for url: https://pypi.org/simple/freeze/ - skipping
2025-03-11T13:18:31,076 Skipping link: not a file: https://pypi.org/simple/freeze/
2025-03-11T13:18:31,083 Given no hashes to check 0 links for project 'freeze': discarding no candidates
2025-03-11T13:18:31,083 ERROR: Could not find a version that satisfies the requirement freeze (from versions: none)
2025-03-11T13:18:31,083 ERROR: No matching distribution found for freeze
2025-03-11T13:18:31,084 Exception information:
2025-03-11T13:18:31,084 Traceback (most recent call last):
2025-03-11T13:18:31,084   File "/home/kevin/Escritorio/universidad/universidad/lib/python3.12/site-packages/pip/_vendor/resolvelib/resolvers.py", line 397, in resolve
2025-03-11T13:18:31,084     self._add_to_criteria(self.state.criteria, r, parent=None)
2025-03-11T13:18:31,084   File "/home/kevin/Escritorio/universidad/universidad/lib/python3.12/site-packages/pip/_vendor/resolvelib/resolvers.py", line 174, in _add_to_criteria
2025-03-11T13:18:31,084     raise RequirementsConflicted(criterion)
2025-03-11T13:18:31,084 pip._vendor.resolvelib.resolvers.RequirementsConflicted: Requirements conflict: SpecifierRequirement('freeze')
2025-03-11T13:18:31,084 
2025-03-11T13:18:31,084 During handling of the above exception, another exception occurred:
2025-03-11T13:18:31,084 
2025-03-11T13:18:31,084 Traceback (most recent call last):
2025-03-11T13:18:31,084   File "/home/kevin/Escritorio/universidad/universidad/lib/python3.12/site-packages/pip/_internal/resolution/resolvelib/resolver.py", line 95, in resolve
2025-03-11T13:18:31,084     result = self._result = resolver.resolve(
2025-03-11T13:18:31,084                             ^^^^^^^^^^^^^^^^^
2025-03-11T13:18:31,084   File "/home/kevin/Escritorio/universidad/universidad/lib/python3.12/site-packages/pip/_vendor/resolvelib/resolvers.py", line 546, in resolve
2025-03-11T13:18:31,084     state = resolution.resolve(requirements, max_rounds=max_rounds)
2025-03-11T13:18:31,084             ^^^^^^^^^^^^^^^^^^^^^^^^^^^^^^^^^^^^^^^^^^^^^^^^^^^^^^^
2025-03-11T13:18:31,084   File "/home/kevin/Escritorio/universidad/universidad/lib/python3.12/site-packages/pip/_vendor/resolvelib/resolvers.py", line 399, in resolve
2025-03-11T13:18:31,084     raise ResolutionImpossible(e.criterion.information)
2025-03-11T13:18:31,084 pip._vendor.resolvelib.resolvers.ResolutionImpossible: [RequirementInformation(requirement=SpecifierRequirement('freeze'), parent=None)]
2025-03-11T13:18:31,084 
2025-03-11T13:18:31,084 The above exception was the direct cause of the following exception:
2025-03-11T13:18:31,084 
2025-03-11T13:18:31,084 Traceback (most recent call last):
2025-03-11T13:18:31,084   File "/home/kevin/Escritorio/universidad/universidad/lib/python3.12/site-packages/pip/_internal/cli/base_command.py", line 180, in exc_logging_wrapper
2025-03-11T13:18:31,084     status = run_func(*args)
2025-03-11T13:18:31,084              ^^^^^^^^^^^^^^^
2025-03-11T13:18:31,084   File "/home/kevin/Escritorio/universidad/universidad/lib/python3.12/site-packages/pip/_internal/cli/req_command.py", line 245, in wrapper
2025-03-11T13:18:31,084     return func(self, options, args)
2025-03-11T13:18:31,084            ^^^^^^^^^^^^^^^^^^^^^^^^^
2025-03-11T13:18:31,084   File "/home/kevin/Escritorio/universidad/universidad/lib/python3.12/site-packages/pip/_internal/commands/install.py", line 377, in run
2025-03-11T13:18:31,084     requirement_set = resolver.resolve(
2025-03-11T13:18:31,084                       ^^^^^^^^^^^^^^^^^
2025-03-11T13:18:31,084   File "/home/kevin/Escritorio/universidad/universidad/lib/python3.12/site-packages/pip/_internal/resolution/resolvelib/resolver.py", line 104, in resolve
2025-03-11T13:18:31,084     raise error from e
2025-03-11T13:18:31,084 pip._internal.exceptions.DistributionNotFound: No matching distribution found for freeze
2025-03-11T13:18:31,085 Removed build tracker: '/tmp/pip-build-tracker-0mmx0nce'
